  0%|                                                    | 0/80 [00:00<?, ?it/s]Exception in thread Thread-4:
0 25113 0.5556656122207642
1 25113 0.6489301323890686
2 25113 0.6017934679985046
3 25113 0.5276564359664917
4 25113 0.5213173627853394
5 25113 0.43446826934814453
6 25113 0.576287567615509
Traceback (most recent call last):
  File "/usr/local/lib/python3.9/threading.py", line 973, in _bootstrap_inner
    self.run()
  File "/usr/local/lib/python3.9/threading.py", line 910, in run
    self._target(*self._args, **self._kwargs)
  File "/usr/local/lib/python3.9/site-packages/torch/utils/data/_utils/pin_memory.py", line 28, in _pin_memory_loop
    r = in_queue.get(timeout=MP_STATUS_CHECK_INTERVAL)
  File "/usr/local/lib/python3.9/multiprocessing/queues.py", line 122, in get
    return _ForkingPickler.loads(res)
  File "/usr/local/lib/python3.9/site-packages/torch/multiprocessing/reductions.py", line 297, in rebuild_storage_fd
    fd = df.detach()
  File "/usr/local/lib/python3.9/multiprocessing/resource_sharer.py", line 57, in detach
    with _resource_sharer.get_connection(self._id) as conn:
  File "/usr/local/lib/python3.9/multiprocessing/resource_sharer.py", line 86, in get_connection
    c = Client(address, authkey=process.current_process().authkey)
  File "/usr/local/lib/python3.9/multiprocessing/connection.py", line 507, in Client
    c = SocketClient(address)
  File "/usr/local/lib/python3.9/multiprocessing/connection.py", line 635, in SocketClient
    s.connect(address)
ConnectionRefusedError: [Errno 111] Connection refused
  0%|                                                    | 0/80 [00:21<?, ?it/s]
Traceback (most recent call last):
  File "/code/RLoc/training/train.py", line 31, in <module>
    do_train(params, debug=args.debug, device=device)
  File "/code/RLoc/training/trainer.py", line 410, in do_train
    torch.cuda.empty_cache()
  File "/usr/local/lib/python3.9/site-packages/torch/cuda/memory.py", line 121, in empty_cache
    torch._C._cuda_emptyCache()
KeyboardInterrupt
