  0%|                                                                                 | 0/120 [00:41<?, ?it/s]
Traceback (most recent call last):
  File "/usr/local/lib/python3.9/site-packages/torch/utils/data/dataloader.py", line 1163, in _try_get_data
    data = self._data_queue.get(timeout=timeout)
  File "/usr/local/lib/python3.9/queue.py", line 180, in get
    self.not_empty.wait(remaining)
  File "/usr/local/lib/python3.9/threading.py", line 316, in wait
    gotit = waiter.acquire(True, timeout)
  File "/usr/local/lib/python3.9/site-packages/torch/utils/data/_utils/signal_handling.py", line 66, in handler
    _error_if_any_worker_fails()
RuntimeError: DataLoader worker (pid 3733) is killed by signal: Killed.

The above exception was the direct cause of the following exception:

Traceback (most recent call last):
  File "/code/RLoc/training/train.py", line 31, in <module>
    do_train(params, debug=args.debug, device=device)
  File "/code/RLoc/training/trainer.py", line 353, in do_train
    for query, positives, negatives in enumerate(dataloaders[phase]):
  File "/usr/local/lib/python3.9/site-packages/torch/utils/data/dataloader.py", line 681, in __next__
    data = self._next_data()
  File "/usr/local/lib/python3.9/site-packages/torch/utils/data/dataloader.py", line 1359, in _next_data
    idx, data = self._get_data()
  File "/usr/local/lib/python3.9/site-packages/torch/utils/data/dataloader.py", line 1315, in _get_data
    success, data = self._try_get_data()
  File "/usr/local/lib/python3.9/site-packages/torch/utils/data/dataloader.py", line 1176, in _try_get_data
    raise RuntimeError('DataLoader worker (pid(s) {}) exited unexpectedly'.format(pids_str)) from e
RuntimeError: DataLoader worker (pid(s) 3733) exited unexpectedly
