  0%|                                                                   | 0/80 [00:17<?, ?it/s]
Traceback (most recent call last):
  File "/code/RLoc/training/train.py", line 31, in <module>
    do_train(params, debug=args.debug, device=device)
  File "/code/RLoc/training/trainer.py", line 391, in do_train
    outputs = model(inputs, n_pos, n_neg)
  File "/usr/local/lib/python3.9/site-packages/torch/nn/modules/module.py", line 1130, in _call_impl
    return forward_call(*input, **kwargs)
  File "/usr/local/lib/python3.9/site-packages/torch/nn/parallel/data_parallel.py", line 168, in forward
    outputs = self.parallel_apply(replicas, inputs, kwargs)
  File "/usr/local/lib/python3.9/site-packages/torch/nn/parallel/data_parallel.py", line 178, in parallel_apply
    return parallel_apply(replicas, inputs, kwargs, self.device_ids[:len(replicas)])
  File "/usr/local/lib/python3.9/site-packages/torch/nn/parallel/parallel_apply.py", line 86, in parallel_apply
    output.reraise()
  File "/usr/local/lib/python3.9/site-packages/torch/_utils.py", line 461, in reraise
    raise exception
RuntimeError: Caught RuntimeError in replica 0 on device 0.
Original Traceback (most recent call last):
  File "/usr/local/lib/python3.9/site-packages/torch/nn/parallel/parallel_apply.py", line 61, in _worker
    output = module(*input, **kwargs)
  File "/usr/local/lib/python3.9/site-packages/torch/nn/modules/module.py", line 1130, in _call_impl
    return forward_call(*input, **kwargs)
  File "/code/RLoc/models/model_factory.py", line 214, in forward
    negatives_embedding = self.common_model(negatives)  # Output: [B * n_neg, D]
  File "/usr/local/lib/python3.9/site-packages/torch/nn/modules/module.py", line 1130, in _call_impl
    return forward_call(*input, **kwargs)
  File "/code/RLoc/models/radar/baseline_nets.py", line 39, in forward
    x = self.fe(x)
  File "/usr/local/lib/python3.9/site-packages/torch/nn/modules/module.py", line 1130, in _call_impl
    return forward_call(*input, **kwargs)
  File "/code/RLoc/models/radar/my_vgg.py", line 274, in forward
    return self.feature_extractor(x)
  File "/usr/local/lib/python3.9/site-packages/torch/nn/modules/module.py", line 1130, in _call_impl
    return forward_call(*input, **kwargs)
  File "/usr/local/lib/python3.9/site-packages/torch/nn/modules/container.py", line 139, in forward
    input = module(input)
  File "/usr/local/lib/python3.9/site-packages/torch/nn/modules/module.py", line 1130, in _call_impl
    return forward_call(*input, **kwargs)
  File "/usr/local/lib/python3.9/site-packages/torch/nn/modules/container.py", line 139, in forward
    input = module(input)
  File "/usr/local/lib/python3.9/site-packages/torch/nn/modules/module.py", line 1130, in _call_impl
    return forward_call(*input, **kwargs)
  File "/code/RLoc/models/radar/my_vgg.py", line 149, in forward
    out = self.conv3(out)
  File "/usr/local/lib/python3.9/site-packages/torch/nn/modules/module.py", line 1130, in _call_impl
    return forward_call(*input, **kwargs)
  File "/usr/local/lib/python3.9/site-packages/torch/nn/modules/conv.py", line 457, in forward
    return self._conv_forward(input, self.weight, self.bias)
  File "/usr/local/lib/python3.9/site-packages/torch/nn/modules/conv.py", line 453, in _conv_forward
    return F.conv2d(input, weight, bias, self.stride,
RuntimeError: CUDA out of memory. Tried to allocate 1.41 GiB (GPU 0; 23.70 GiB total capacity; 21.12 GiB already allocated; 752.06 MiB free; 21.26 GiB reserved in total by PyTorch) If reserved memory is >> allocated memory try setting max_split_size_mb to avoid fragmentation.  See documentation for Memory Management and PYTORCH_CUDA_ALLOC_CONF
