  0%|                                                    | 0/80 [00:07<?, ?it/s]
Traceback (most recent call last):
  File "/code/RLoc/training/train.py", line 31, in <module>
    do_train(params, debug=args.debug, device=device)
  File "/code/RLoc/training/trainer.py", line 393, in do_train
    outputs = model(inputs, n_pos, n_neg)
  File "/usr/local/lib/python3.9/site-packages/torch/nn/modules/module.py", line 1130, in _call_impl
    return forward_call(*input, **kwargs)
  File "/usr/local/lib/python3.9/site-packages/torch/nn/parallel/data_parallel.py", line 168, in forward
    outputs = self.parallel_apply(replicas, inputs, kwargs)
  File "/usr/local/lib/python3.9/site-packages/torch/nn/parallel/data_parallel.py", line 178, in parallel_apply
    return parallel_apply(replicas, inputs, kwargs, self.device_ids[:len(replicas)])
  File "/usr/local/lib/python3.9/site-packages/torch/nn/parallel/parallel_apply.py", line 86, in parallel_apply
    output.reraise()
  File "/usr/local/lib/python3.9/site-packages/torch/_utils.py", line 461, in reraise
    raise exception
RuntimeError: Caught RuntimeError in replica 0 on device 0.
Original Traceback (most recent call last):
  File "/usr/local/lib/python3.9/site-packages/torch/nn/parallel/parallel_apply.py", line 61, in _worker
    output = module(*input, **kwargs)
  File "/usr/local/lib/python3.9/site-packages/torch/nn/modules/module.py", line 1130, in _call_impl
    return forward_call(*input, **kwargs)
  File "/code/RLoc/models/model_factory.py", line 212, in forward
    query_embedding = self.query_model(query)  # Output: [B, D]
  File "/usr/local/lib/python3.9/site-packages/torch/nn/modules/module.py", line 1130, in _call_impl
    return forward_call(*input, **kwargs)
  File "/code/RLoc/models/radar/baseline_nets.py", line 45, in forward
    x = self.fe(x)
  File "/usr/local/lib/python3.9/site-packages/torch/nn/modules/module.py", line 1130, in _call_impl
    return forward_call(*input, **kwargs)
  File "/code/RLoc/models/radar/my_vgg.py", line 601, in forward
    sparse_input = self._image_to_sparse_tensor(x)
  File "/code/RLoc/models/radar/my_vgg.py", line 566, in _image_to_sparse_tensor
    return ME.SparseTensor(
  File "/usr/local/lib/python3.9/site-packages/MinkowskiEngine-0.5.4-py3.9-linux-x86_64.egg/MinkowskiEngine/MinkowskiSparseTensor.py", line 275, in __init__
    coordinates, features, coordinate_map_key = self.initialize_coordinates(
  File "/usr/local/lib/python3.9/site-packages/MinkowskiEngine-0.5.4-py3.9-linux-x86_64.egg/MinkowskiEngine/MinkowskiSparseTensor.py", line 304, in initialize_coordinates
    ) = self._manager.insert_and_map(coordinates, *coordinate_map_key.get_key())
  File "/usr/local/lib/python3.9/site-packages/MinkowskiEngine-0.5.4-py3.9-linux-x86_64.egg/MinkowskiEngine/MinkowskiCoordinateManager.py", line 179, in insert_and_map
    return self._manager.insert_and_map(coordinates, tensor_stride, string_id)
RuntimeError: CUDA error encountered at: /workspace/MinkowskiEngine/src/3rdparty/concurrent_unordered_map.cuh:595: 209 cudaErrorNoKernelImageForDevice no kernel image is available for execution on the device
