  0%|                                                                     | 0/120 [00:13<?, ?it/s]
Traceback (most recent call last):
  File "/code/RLoc/training/train.py", line 31, in <module>
    do_train(params, debug=args.debug, device=device)
  File "/code/RLoc/training/trainer.py", line 391, in do_train
    outputs = model(inputs, n_pos, n_neg)
  File "/usr/local/lib/python3.9/site-packages/torch/nn/modules/module.py", line 1130, in _call_impl
    return forward_call(*input, **kwargs)
  File "/usr/local/lib/python3.9/site-packages/torch/nn/parallel/data_parallel.py", line 168, in forward
    outputs = self.parallel_apply(replicas, inputs, kwargs)
  File "/usr/local/lib/python3.9/site-packages/torch/nn/parallel/data_parallel.py", line 178, in parallel_apply
    return parallel_apply(replicas, inputs, kwargs, self.device_ids[:len(replicas)])
  File "/usr/local/lib/python3.9/site-packages/torch/nn/parallel/parallel_apply.py", line 86, in parallel_apply
    output.reraise()
  File "/usr/local/lib/python3.9/site-packages/torch/_utils.py", line 461, in reraise
    raise exception
RuntimeError: Caught RuntimeError in replica 0 on device 0.
Original Traceback (most recent call last):
  File "/usr/local/lib/python3.9/site-packages/torch/nn/parallel/parallel_apply.py", line 61, in _worker
    output = module(*input, **kwargs)
  File "/usr/local/lib/python3.9/site-packages/torch/nn/modules/module.py", line 1130, in _call_impl
    return forward_call(*input, **kwargs)
  File "/code/RLoc/models/model_factory.py", line 145, in forward
    query_embedding = self.query_model(query)  # Output: [B, D]
  File "/usr/local/lib/python3.9/site-packages/torch/nn/modules/module.py", line 1130, in _call_impl
    return forward_call(*input, **kwargs)
  File "/code/RLoc/models/radar/radar_net.py", line 52, in forward
    x2 = self.vit(x_upper)      # Apply ViT (B, N)
  File "/usr/local/lib/python3.9/site-packages/torch/nn/modules/module.py", line 1130, in _call_impl
    return forward_call(*input, **kwargs)
  File "/usr/local/lib/python3.9/site-packages/vit_pytorch/vit_for_small_dataset.py", line 127, in forward
    x = self.to_patch_embedding(img)
  File "/usr/local/lib/python3.9/site-packages/torch/nn/modules/module.py", line 1130, in _call_impl
    return forward_call(*input, **kwargs)
  File "/usr/local/lib/python3.9/site-packages/vit_pytorch/vit_for_small_dataset.py", line 96, in forward
    return self.to_patch_tokens(x_with_shifts)
  File "/usr/local/lib/python3.9/site-packages/torch/nn/modules/module.py", line 1130, in _call_impl
    return forward_call(*input, **kwargs)
  File "/usr/local/lib/python3.9/site-packages/torch/nn/modules/container.py", line 139, in forward
    input = module(input)
  File "/usr/local/lib/python3.9/site-packages/torch/nn/modules/module.py", line 1130, in _call_impl
    return forward_call(*input, **kwargs)
  File "/usr/local/lib/python3.9/site-packages/torch/nn/modules/normalization.py", line 189, in forward
    return F.layer_norm(
  File "/usr/local/lib/python3.9/site-packages/torch/nn/functional.py", line 2503, in layer_norm
    return torch.layer_norm(input, normalized_shape, weight, bias, eps, torch.backends.cudnn.enabled)
RuntimeError: Given normalized_shape=[3840], expected input with shape [*, 3840], but got input of size[100, 144, 1280]
