  0%|                                                                   | 0/80 [00:00<?, ?it/s]Exception ignored in: <function _MultiProcessingDataLoaderIter.__del__ at 0x7fe07dfb0040>
0 25113 2.938462734222412
1 25113 2.765836238861084
2 25113 2.3625612258911133
3 25113 2.180191993713379
4 25113 2.2118091583251953
5 25113 1.757225513458252
Traceback (most recent call last):
  File "/usr/local/lib/python3.9/site-packages/torch/utils/data/dataloader.py", line 1510, in __del__
    self._shutdown_workers()
  File "/usr/local/lib/python3.9/site-packages/torch/utils/data/dataloader.py", line 1474, in _shutdown_workers
    w.join(timeout=_utils.MP_STATUS_CHECK_INTERVAL)
  File "/usr/local/lib/python3.9/multiprocessing/process.py", line 149, in join
    res = self._popen.wait(timeout)
  File "/usr/local/lib/python3.9/multiprocessing/popen_fork.py", line 40, in wait
    if not wait([self.sentinel], timeout):
  File "/usr/local/lib/python3.9/multiprocessing/connection.py", line 936, in wait
    ready = selector.select(timeout)
  File "/usr/local/lib/python3.9/selectors.py", line 416, in select
    fd_event_list = self._selector.poll(timeout)
  File "/usr/local/lib/python3.9/site-packages/torch/utils/data/_utils/signal_handling.py", line 66, in handler
    _error_if_any_worker_fails()
RuntimeError: DataLoader worker (pid 20244) exited unexpectedly with exit code 1. Details are lost due to multiprocessing. Rerunning with num_workers=0 may give better error trace.
  0%|                                                                   | 0/80 [00:22<?, ?it/s]
Traceback (most recent call last):
  File "/code/RLoc/training/train.py", line 31, in <module>
    do_train(params, debug=args.debug, device=device)
  File "/code/RLoc/training/trainer.py", line 408, in do_train
    torch.cuda.empty_cache()
  File "/usr/local/lib/python3.9/site-packages/torch/cuda/memory.py", line 121, in empty_cache
    torch._C._cuda_emptyCache()
KeyboardInterrupt
